Workbook

Sheet 월별 비교
A1: 태향 거래처원장 vs 미션글로벌 매출·매입 — 월별 대사표 (2025.01 ~ 2026.09)
A2: 원장 금액은 대금 결제(입금·지급)를 제외한 거래분만 집계. 모든 숫자는 「대사내역」 시트에서 SUMIFS로 계산.
A4: 연도 | B4: 월 | C4: 원장 차변 (태향→미션 판매) | D4: 미션 매입 | E4: 차이 | F4: 원장 대변 (상계·미션 판매분) | G4: 미션 매출 | H4: 차이 | I4: 불일치 건수 | J4: 판정
A5: 2025 | B5: 1 | C5: =SUMIFS(대사내역!$F$2:$F$113,대사내역!$A$2:$A$113,$A5,대사내역!$B$2:$B$113,$B5,대사내역!$C$2:$C$113,"매입") -> 190900129 | D5: =SUMIFS(대사내역!$K$2:$K$113,대사내역!$A$2:$A$113,$A5,대사내역!$B$2:$B$113,$B5,대사내역!$C$2:$C$113,"매입") -> 190900129 | E5: =C5-D5 -> 0 | F5: =SUMIFS(대사내역!$F$2:$F$113,대사내역!$A$2:$A$113,$A5,대사내역!$B$2:$B$113,$B5,대사내역!$C$2:$C$113,"매출") -> 11193209 | G5: =SUMIFS(대사내역!$K$2:$K$113,대사내역!$A$2:$A$113,$A5,대사내역!$B$2:$B$113,$B5,대사내역!$C$2:$C$113,"매출") -> 11193209 | H5: =F5-G5 -> 0 | I5: =COUNTIFS(대사내역!$A$2:$A$113,$A5,대사내역!$B$2:$B$113,$B5,대사내역!$M$2:$M$113,"<>일치") -> 0 | J5: =IF(AND(E5=0,H5=0,I5=0),"일치","차이") -> 일치
A6: 2025 | B6: 2 | C6: =SUMIFS(대사내역!$F$2:$F$113,대사내역!$A$2:$A$113,$A6,대사내역!$B$2:$B$113,$B6,대사내역!$C$2:$C$113,"매입") -> 101126356 | D6: =SUMIFS(대사내역!$K$2:$K$113,대사내역!$A$2:$A$113,$A6,대사내역!$B$2:$B$113,$B6,대사내역!$C$2:$C$113,"매입") -> 101126356 | E6: =C6-D6 -> 0 | F6: =SUMIFS(대사내역!$F$2:$F$113,대사내역!$A$2:$A$113,$A6,대사내역!$B$2:$B$113,$B6,대사내역!$C$2:$C$113,"매출") -> 35266495 | G6: =SUMIFS(대사내역!$K$2:$K$113,대사내역!$A$2:$A$113,$A6,대사내역!$B$2:$B$113,$B6,대사내역!$C$2:$C$113,"매출") -> 35266495 | H6: =F6-G6 -> 0 | I6: =COUNTIFS(대사내역!$A$2:$A$113,$A6,대사내역!$B$2:$B$113,$B6,대사내역!$M$2:$M$113,"<>일치") -> 0 | J6: =IF(AND(E6=0,H6=0,I6=0),"일치","차이") -> 일치
A7: 2025 | B7: 3 | C7: =SUMIFS(대사내역!$F$2:$F$113,대사내역!$A$2:$A$113,$A7,대사내역!$B$2:$B$113,$B7,대사내역!$C$2:$C$113,"매입") -> 85233747 | D7: =SUMIFS(대사내역!$K$2:$K$113,대사내역!$A$2:$A$113,$A7,대사내역!$B$2:$B$113,$B7,대사내역!$C$2:$C$113,"매입") -> 84383297 | E7: =C7-D7 -> 850450 | F7: =SUMIFS(대사내역!$F$2:$F$113,대사내역!$A$2:$A$113,$A7,대사내역!$B$2:$B$113,$B7,대사내역!$C$2:$C$113,"매출") -> 12562751 | G7: =SUMIFS(대사내역!$K$2:$K$113,대사내역!$A$2:$A$113,$A7,대사내역!$B$2:$B$113,$B7,대사내역!$C$2:$C$113,"매출") -> 11712301 | H7: =F7-G7 -> 850450 | I7: =COUNTIFS(대사내역!$A$2:$A$113,$A7,대사내역!$B$2:$B$113,$B7,대사내역!$M$2:$M$113,"<>일치") -> 2 | J7: =IF(AND(E7=0,H7=0,I7=0),"일치","차이") -> 차이
A8: 2025 | B8: 4 | C8: =SUMIFS(대사내역!$F$2:$F$113,대사내역!$A$2:$A$113,$A8,대사내역!$B$2:$B$113,$B8,대사내역!$C$2:$C$113,"매입") -> 191093851 | D8: =SUMIFS(대사내역!$K$2:$K$113,대사내역!$A$2:$A$113,$A8,대사내역!$B$2:$B$113,$B8,대사내역!$C$2:$C$113,"매입") -> 191093851 | E8: =C8-D8 -> 0 | F8: =SUMIFS(대사내역!$F$2:$F$113,대사내역!$A$2:$A$113,$A8,대사내역!$B$2:$B$113,$B8,대사내역!$C$2:$C$113,"매출") -> 15255923 | G8: =SUMIFS(대사내역!$K$2:$K$113,대사내역!$A$2:$A$113,$A8,대사내역!$B$2:$B$113,$B8,대사내역!$C$2:$C$113,"매출") -> 15255923 | H8: =F8-G8 -> 0 | I8: =COUNTIFS(대사내역!$A$2:$A$113,$A8,대사내역!$B$2:$B$113,$B8,대사내역!$M$2:$M$113,"<>일치") -> 0 | J8: =IF(AND(E8=0,H8=0,I8=0),"일치","차이") -> 일치
A9: 2025 | B9: 5 | C9: =SUMIFS(대사내역!$F$2:$F$113,대사내역!$A$2:$A$113,$A9,대사내역!$B$2:$B$113,$B9,대사내역!$C$2:$C$113,"매입") -> 182848696 | D9: =SUMIFS(대사내역!$K$2:$K$113,대사내역!$A$2:$A$113,$A9,대사내역!$B$2:$B$113,$B9,대사내역!$C$2:$C$113,"매입") -> 182848696 | E9: =C9-D9 -> 0 | F9: =SUMIFS(대사내역!$F$2:$F$113,대사내역!$A$2:$A$113,$A9,대사내역!$B$2:$B$113,$B9,대사내역!$C$2:$C$113,"매출") -> 60394103 | G9: =SUMIFS(대사내역!$K$2:$K$113,대사내역!$A$2:$A$113,$A9,대사내역!$B$2:$B$113,$B9,대사내역!$C$2:$C$113,"매출") -> 60394103 | H9: =F9-G9 -> 0 | I9: =COUNTIFS(대사내역!$A$2:$A$113,$A9,대사내역!$B$2:$B$113,$B9,대사내역!$M$2:$M$113,"<>일치") -> 0 | J9: =IF(AND(E9=0,H9=0,I9=0),"일치","차이") -> 일치
A10: 2025 | B10: 6 | C10: =SUMIFS(대사내역!$F$2:$F$113,대사내역!$A$2:$A$113,$A10,대사내역!$B$2:$B$113,$B10,대사내역!$C$2:$C$113,"매입") -> 193523201 | D10: =SUMIFS(대사내역!$K$2:$K$113,대사내역!$A$2:$A$113,$A10,대사내역!$B$2:$B$113,$B10,대사내역!$C$2:$C$113,"매입") -> 193523201 | E10: =C10-D10 -> 0 | F10: =SUMIFS(대사내역!$F$2:$F$113,대사내역!$A$2:$A$113,$A10,대사내역!$B$2:$B$113,$B10,대사내역!$C$2:$C$113,"매출") -> 12435198 | G10: =SUMIFS(대사내역!$K$2:$K$113,대사내역!$A$2:$A$113,$A10,대사내역!$B$2:$B$113,$B10,대사내역!$C$2:$C$113,"매출") -> 12435198 | H10: =F10-G10 -> 0 | I10: =COUNTIFS(대사내역!$A$2:$A$113,$A10,대사내역!$B$2:$B$113,$B10,대사내역!$M$2:$M$113,"<>일치") -> 0 | J10: =IF(AND(E10=0,H10=0,I10=0),"일치","차이") -> 일치
A11: 2025 | B11: 7 | C11: =SUMIFS(대사내역!$F$2:$F$113,대사내역!$A$2:$A$113,$A11,대사내역!$B$2:$B$113,$B11,대사내역!$C$2:$C$113,"매입") -> 178164371 | D11: =SUMIFS(대사내역!$K$2:$K$113,대사내역!$A$2:$A$113,$A11,대사내역!$B$2:$B$113,$B11,대사내역!$C$2:$C$113,"매입") -> 178164371 | E11: =C11-D11 -> 0 | F11: =SUMIFS(대사내역!$F$2:$F$113,대사내역!$A$2:$A$113,$A11,대사내역!$B$2:$B$113,$B11,대사내역!$C$2:$C$113,"매출") -> 13924084 | G11: =SUMIFS(대사내역!$K$2:$K$113,대사내역!$A$2:$A$113,$A11,대사내역!$B$2:$B$113,$B11,대사내역!$C$2:$C$113,"매출") -> 13924084 | H11: =F11-G11 -> 0 | I11: =COUNTIFS(대사내역!$A$2:$A$113,$A11,대사내역!$B$2:$B$113,$B11,대사내역!$M$2:$M$113,"<>일치") -> 0 | J11: =IF(AND(E11=0,H11=0,I11=0),"일치","차이") -> 일치
A12: 2025 | B12: 8 | C12: =SUMIFS(대사내역!$F$2:$F$113,대사내역!$A$2:$A$113,$A12,대사내역!$B$2:$B$113,$B12,대사내역!$C$2:$C$113,"매입") -> 186124546 | D12: =SUMIFS(대사내역!$K$2:$K$113,대사내역!$A$2:$A$113,$A12,대사내역!$B$2:$B$113,$B12,대사내역!$C$2:$C$113,"매입") -> 186124546 | E12: =C12-D12 -> 0 | F12: =SUMIFS(대사내역!$F$2:$F$113,대사내역!$A$2:$A$113,$A12,대사내역!$B$2:$B$113,$B12,대사내역!$C$2:$C$113,"매출") -> 14549997 | G12: =SUMIFS(대사내역!$K$2:$K$113,대사내역!$A$2:$A$113,$A12,대사내역!$B$2:$B$113,$B12,대사내역!$C$2:$C$113,"매출") -> 14549997 | H12: =F12-G12 -> 0 | I12: =COUNTIFS(대사내역!$A$2:$A$113,$A12,대사내역!$B$2:$B$113,$B12,대사내역!$M$2:$M$113,"<>일치") -> 0 | J12: =IF(AND(E12=0,H12=0,I12=0),"일치","차이") -> 일치
A13: 2025 | B13: 9 | C13: =SUMIFS(대사내역!$F$2:$F$113,대사내역!$A$2:$A$113,$A13,대사내역!$B$2:$B$113,$B13,대사내역!$C$2:$C$113,"매입") -> 192386722 | D13: =SUMIFS(대사내역!$K$2:$K$113,대사내역!$A$2:$A$113,$A13,대사내역!$B$2:$B$113,$B13,대사내역!$C$2:$C$113,"매입") -> 192386722 | E13: =C13-D13 -> 0 | F13: =SUMIFS(대사내역!$F$2:$F$113,대사내역!$A$2:$A$113,$A13,대사내역!$B$2:$B$113,$B13,대사내역!$C$2:$C$113,"매출") -> 15010317 | G13: =SUMIFS(대사내역!$K$2:$K$113,대사내역!$A$2:$A$113,$A13,대사내역!$B$2:$B$113,$B13,대사내역!$C$2:$C$113,"매출") -> 15010317 | H13: =F13-G13 -> 0 | I13: =COUNTIFS(대사내역!$A$2:$A$113,$A13,대사내역!$B$2:$B$113,$B13,대사내역!$M$2:$M$113,"<>일치") -> 0 | J13: =IF(AND(E13=0,H13=0,I13=0),"일치","차이") -> 일치
A14: 2025 | B14: 10 | C14: =SUMIFS(대사내역!$F$2:$F$113,대사내역!$A$2:$A$113,$A14,대사내역!$B$2:$B$113,$B14,대사내역!$C$2:$C$113,"매입") -> 210740227 | D14: =SUMIFS(대사내역!$K$2:$K$113,대사내역!$A$2:$A$113,$A14,대사내역!$B$2:$B$113,$B14,대사내역!$C$2:$C$113,"매입") -> 210740227 | E14: =C14-D14 -> 0 | F14: =SUMIFS(대사내역!$F$2:$F$113,대사내역!$A$2:$A$113,$A14,대사내역!$B$2:$B$113,$B14,대사내역!$C$2:$C$113,"매출") -> 8605620 | G14: =SUMIFS(대사내역!$K$2:$K$113,대사내역!$A$2:$A$113,$A14,대사내역!$B$2:$B$113,$B14,대사내역!$C$2:$C$113,"매출") -> 8605620 | H14: =F14-G14 -> 0 | I14: =COUNTIFS(대사내역!$A$2:$A$113,$A14,대사내역!$B$2:$B$113,$B14,대사내역!$M$2:$M$113,"<>일치") -> 0 | J14: =IF(AND(E14=0,H14=0,I14=0),"일치","차이") -> 일치
A15: 2025 | B15: 11 | C15: =SUMIFS(대사내역!$F$2:$F$113,대사내역!$A$2:$A$113,$A15,대사내역!$B$2:$B$113,$B15,대사내역!$C$2:$C$113,"매입") -> 141166703 | D15: =SUMIFS(대사내역!$K$2:$K$113,대사내역!$A$2:$A$113,$A15,대사내역!$B$2:$B$113,$B15,대사내역!$C$2:$C$113,"매입") -> 141166703 | E15: =C15-D15 -> 0 | F15: =SUMIFS(대사내역!$F$2:$F$113,대사내역!$A$2:$A$113,$A15,대사내역!$B$2:$B$113,$B15,대사내역!$C$2:$C$113,"매출") -> 8435057 | G15: =SUMIFS(대사내역!$K$2:$K$113,대사내역!$A$2:$A$113,$A15,대사내역!$B$2:$B$113,$B15,대사내역!$C$2:$C$113,"매출") -> 8435057 | H15: =F15-G15 -> 0 | I15: =COUNTIFS(대사내역!$A$2:$A$113,$A15,대사내역!$B$2:$B$113,$B15,대사내역!$M$2:$M$113,"<>일치") -> 0 | J15: =IF(AND(E15=0,H15=0,I15=0),"일치","차이") -> 일치
A16: 2025 | B16: 12 | C16: =SUMIFS(대사내역!$F$2:$F$113,대사내역!$A$2:$A$113,$A16,대사내역!$B$2:$B$113,$B16,대사내역!$C$2:$C$113,"매입") -> 78527196 | D16: =SUMIFS(대사내역!$K$2:$K$113,대사내역!$A$2:$A$113,$A16,대사내역!$B$2:$B$113,$B16,대사내역!$C$2:$C$113,"매입") -> 78527196 | E16: =C16-D16 -> 0 | F16: =SUMIFS(대사내역!$F$2:$F$113,대사내역!$A$2:$A$113,$A16,대사내역!$B$2:$B$113,$B16,대사내역!$C$2:$C$113,"매출") -> -202950 | G16: =SUMIFS(대사내역!$K$2:$K$113,대사내역!$A$2:$A$113,$A16,대사내역!$B$2:$B$113,$B16,대사내역!$C$2:$C$113,"매출") -> 0 | H16: =F16-G16 -> -202950 | I16: =COUNTIFS(대사내역!$A$2:$A$113,$A16,대사내역!$B$2:$B$113,$B16,대사내역!$M$2:$M$113,"<>일치") -> 1 | J16: =IF(AND(E16=0,H16=0,I16=0),"일치","차이") -> 차이
A17: 2025 합계 | C17: =SUM(C5:C16) -> 1931835745 | D17: =SUM(D5:D16) -> 1930985295 | E17: =SUM(E5:E16) -> 850450 | F17: =SUM(F5:F16) -> 207429804 | G17: =SUM(G5:G16) -> 206782304 | H17: =SUM(H5:H16) -> 647500 | I17: =SUM(I5:I16) -> 3 | J17: =IF(AND(E17=0,H17=0,I17=0),"일치","차이") -> 차이
A19: 2026 | B19: 1 | C19: =SUMIFS(대사내역!$F$2:$F$113,대사내역!$A$2:$A$113,$A19,대사내역!$B$2:$B$113,$B19,대사내역!$C$2:$C$113,"매입") -> 141400106 | D19: =SUMIFS(대사내역!$K$2:$K$113,대사내역!$A$2:$A$113,$A19,대사내역!$B$2:$B$113,$B19,대사내역!$C$2:$C$113,"매입") -> 141400106 | E19: =C19-D19 -> 0 | F19: =SUMIFS(대사내역!$F$2:$F$113,대사내역!$A$2:$A$113,$A19,대사내역!$B$2:$B$113,$B19,대사내역!$C$2:$C$113,"매출") -> 20575995 | G19: =SUMIFS(대사내역!$K$2:$K$113,대사내역!$A$2:$A$113,$A19,대사내역!$B$2:$B$113,$B19,대사내역!$C$2:$C$113,"매출") -> 20575995 | H19: =F19-G19 -> 0 | I19: =COUNTIFS(대사내역!$A$2:$A$113,$A19,대사내역!$B$2:$B$113,$B19,대사내역!$M$2:$M$113,"<>일치") -> 0 | J19: =IF(AND(E19=0,H19=0,I19=0),"일치","차이") -> 일치
A20: 2026 | B20: 2 | C20: =SUMIFS(대사내역!$F$2:$F$113,대사내역!$A$2:$A$113,$A20,대사내역!$B$2:$B$113,$B20,대사내역!$C$2:$C$113,"매입") -> 98615812 | D20: =SUMIFS(대사내역!$K$2:$K$113,대사내역!$A$2:$A$113,$A20,대사내역!$B$2:$B$113,$B20,대사내역!$C$2:$C$113,"매입") -> 98615812 | E20: =C20-D20 -> 0 | F20: =SUMIFS(대사내역!$F$2:$F$113,대사내역!$A$2:$A$113,$A20,대사내역!$B$2:$B$113,$B20,대사내역!$C$2:$C$113,"매출") -> 0 | G20: =SUMIFS(대사내역!$K$2:$K$113,대사내역!$A$2:$A$113,$A20,대사내역!$B$2:$B$113,$B20,대사내역!$C$2:$C$113,"매출") -> 0 | H20: =F20-G20 -> 0 | I20: =COUNTIFS(대사내역!$A$2:$A$113,$A20,대사내역!$B$2:$B$113,$B20,대사내역!$M$2:$M$113,"<>일치") -> 0 | J20: =IF(AND(E20=0,H20=0,I20=0),"일치","차이") -> 일치
A21: 2026 | B21: 3 | C21: =SUMIFS(대사내역!$F$2:$F$113,대사내역!$A$2:$A$113,$A21,대사내역!$B$2:$B$113,$B21,대사내역!$C$2:$C$113,"매입") -> 467883394 | D21: =SUMIFS(대사내역!$K$2:$K$113,대사내역!$A$2:$A$113,$A21,대사내역!$B$2:$B$113,$B21,대사내역!$C$2:$C$113,"매입") -> 467883394 | E21: =C21-D21 -> 0 | F21: =SUMIFS(대사내역!$F$2:$F$113,대사내역!$A$2:$A$113,$A21,대사내역!$B$2:$B$113,$B21,대사내역!$C$2:$C$113,"매출") -> 26780167 | G21: =SUMIFS(대사내역!$K$2:$K$113,대사내역!$A$2:$A$113,$A21,대사내역!$B$2:$B$113,$B21,대사내역!$C$2:$C$113,"매출") -> 26780167 | H21: =F21-G21 -> 0 | I21: =COUNTIFS(대사내역!$A$2:$A$113,$A21,대사내역!$B$2:$B$113,$B21,대사내역!$M$2:$M$113,"<>일치") -> 0 | J21: =IF(AND(E21=0,H21=0,I21=0),"일치","차이") -> 일치
A22: 2026 | B22: 4 | C22: =SUMIFS(대사내역!$F$2:$F$113,대사내역!$A$2:$A$113,$A22,대사내역!$B$2:$B$113,$B22,대사내역!$C$2:$C$113,"매입") -> 89480492 | D22: =SUMIFS(대사내역!$K$2:$K$113,대사내역!$A$2:$A$113,$A22,대사내역!$B$2:$B$113,$B22,대사내역!$C$2:$C$113,"매입") -> 89480492 | E22: =C22-D22 -> 0 | F22: =SUMIFS(대사내역!$F$2:$F$113,대사내역!$A$2:$A$113,$A22,대사내역!$B$2:$B$113,$B22,대사내역!$C$2:$C$113,"매출") -> 96566621 | G22: =SUMIFS(대사내역!$K$2:$K$113,대사내역!$A$2:$A$113,$A22,대사내역!$B$2:$B$113,$B22,대사내역!$C$2:$C$113,"매출") -> 96566621 | H22: =F22-G22 -> 0 | I22: =COUNTIFS(대사내역!$A$2:$A$113,$A22,대사내역!$B$2:$B$113,$B22,대사내역!$M$2:$M$113,"<>일치") -> 0 | J22: =IF(AND(E22=0,H22=0,I22=0),"일치","차이") -> 일치
A23: 2026 | B23: 5 | C23: =SUMIFS(대사내역!$F$2:$F$113,대사내역!$A$2:$A$113,$A23,대사내역!$B$2:$B$113,$B23,대사내역!$C$2:$C$113,"매입") -> 171576529 | D23: =SUMIFS(대사내역!$K$2:$K$113,대사내역!$A$2:$A$113,$A23,대사내역!$B$2:$B$113,$B23,대사내역!$C$2:$C$113,"매입") -> 171576529 | E23: =C23-D23 -> 0 | F23: =SUMIFS(대사내역!$F$2:$F$113,대사내역!$A$2:$A$113,$A23,대사내역!$B$2:$B$113,$B23,대사내역!$C$2:$C$113,"매출") -> 99764713 | G23: =SUMIFS(대사내역!$K$2:$K$113,대사내역!$A$2:$A$113,$A23,대사내역!$B$2:$B$113,$B23,대사내역!$C$2:$C$113,"매출") -> 99764713 | H23: =F23-G23 -> 0 | I23: =COUNTIFS(대사내역!$A$2:$A$113,$A23,대사내역!$B$2:$B$113,$B23,대사내역!$M$2:$M$113,"<>일치") -> 0 | J23: =IF(AND(E23=0,H23=0,I23=0),"일치","차이") -> 일치
A24: 2026 | B24: 6 | C24: =SUMIFS(대사내역!$F$2:$F$113,대사내역!$A$2:$A$113,$A24,대사내역!$B$2:$B$113,$B24,대사내역!$C$2:$C$113,"매입") -> 258214913 | D24: =SUMIFS(대사내역!$K$2:$K$113,대사내역!$A$2:$A$113,$A24,대사내역!$B$2:$B$113,$B24,대사내역!$C$2:$C$113,"매입") -> 258214913 | E24: =C24-D24 -> 0 | F24: =SUMIFS(대사내역!$F$2:$F$113,대사내역!$A$2:$A$113,$A24,대사내역!$B$2:$B$113,$B24,대사내역!$C$2:$C$113,"매출") -> -36903535 | G24: =SUMIFS(대사내역!$K$2:$K$113,대사내역!$A$2:$A$113,$A24,대사내역!$B$2:$B$113,$B24,대사내역!$C$2:$C$113,"매출") -> -36903535 | H24: =F24-G24 -> 0 | I24: =COUNTIFS(대사내역!$A$2:$A$113,$A24,대사내역!$B$2:$B$113,$B24,대사내역!$M$2:$M$113,"<>일치") -> 0 | J24: =IF(AND(E24=0,H24=0,I24=0),"일치","차이") -> 일치
A25: 2026 | B25: 7 | C25: =SUMIFS(대사내역!$F$2:$F$113,대사내역!$A$2:$A$113,$A25,대사내역!$B$2:$B$113,$B25,대사내역!$C$2:$C$113,"매입") -> 203572129 | D25: =SUMIFS(대사내역!$K$2:$K$113,대사내역!$A$2:$A$113,$A25,대사내역!$B$2:$B$113,$B25,대사내역!$C$2:$C$113,"매입") -> 203572129 | E25: =C25-D25 -> 0 | F25: =SUMIFS(대사내역!$F$2:$F$113,대사내역!$A$2:$A$113,$A25,대사내역!$B$2:$B$113,$B25,대사내역!$C$2:$C$113,"매출") -> 284531 | G25: =SUMIFS(대사내역!$K$2:$K$113,대사내역!$A$2:$A$113,$A25,대사내역!$B$2:$B$113,$B25,대사내역!$C$2:$C$113,"매출") -> 284531 | H25: =F25-G25 -> 0 | I25: =COUNTIFS(대사내역!$A$2:$A$113,$A25,대사내역!$B$2:$B$113,$B25,대사내역!$M$2:$M$113,"<>일치") -> 0 | J25: =IF(AND(E25=0,H25=0,I25=0),"일치","차이") -> 일치
A26: 2026 | B26: 8 | C26: =SUMIFS(대사내역!$F$2:$F$113,대사내역!$A$2:$A$113,$A26,대사내역!$B$2:$B$113,$B26,대사내역!$C$2:$C$113,"매입") -> 159014061 | D26: =SUMIFS(대사내역!$K$2:$K$113,대사내역!$A$2:$A$113,$A26,대사내역!$B$2:$B$113,$B26,대사내역!$C$2:$C$113,"매입") -> 159014061 | E26: =C26-D26 -> 0 | F26: =SUMIFS(대사내역!$F$2:$F$113,대사내역!$A$2:$A$113,$A26,대사내역!$B$2:$B$113,$B26,대사내역!$C$2:$C$113,"매출") -> 23463006 | G26: =SUMIFS(대사내역!$K$2:$K$113,대사내역!$A$2:$A$113,$A26,대사내역!$B$2:$B$113,$B26,대사내역!$C$2:$C$113,"매출") -> 23463006 | H26: =F26-G26 -> 0 | I26: =COUNTIFS(대사내역!$A$2:$A$113,$A26,대사내역!$B$2:$B$113,$B26,대사내역!$M$2:$M$113,"<>일치") -> 0 | J26: =IF(AND(E26=0,H26=0,I26=0),"일치","차이") -> 일치
A27: 2026 | B27: 9 | C27: =SUMIFS(대사내역!$F$2:$F$113,대사내역!$A$2:$A$113,$A27,대사내역!$B$2:$B$113,$B27,대사내역!$C$2:$C$113,"매입") -> 19459211 | D27: =SUMIFS(대사내역!$K$2:$K$113,대사내역!$A$2:$A$113,$A27,대사내역!$B$2:$B$113,$B27,대사내역!$C$2:$C$113,"매입") -> 21619524 | E27: =C27-D27 -> -2160313 | F27: =SUMIFS(대사내역!$F$2:$F$113,대사내역!$A$2:$A$113,$A27,대사내역!$B$2:$B$113,$B27,대사내역!$C$2:$C$113,"매출") -> 0 | G27: =SUMIFS(대사내역!$K$2:$K$113,대사내역!$A$2:$A$113,$A27,대사내역!$B$2:$B$113,$B27,대사내역!$C$2:$C$113,"매출") -> 0 | H27: =F27-G27 -> 0 | I27: =COUNTIFS(대사내역!$A$2:$A$113,$A27,대사내역!$B$2:$B$113,$B27,대사내역!$M$2:$M$113,"<>일치") -> 1 | J27: =IF(AND(E27=0,H27=0,I27=0),"일치","차이") -> 차이
A28: 2026 합계 | C28: =SUM(C19:C27) -> 1609216647 | D28: =SUM(D19:D27) -> 1611376960 | E28: =SUM(E19:E27) -> -2160313 | F28: =SUM(F19:F27) -> 230531498 | G28: =SUM(G19:G27) -> 230531498 | H28: =SUM(H19:H27) -> 0 | I28: =SUM(I19:I27) -> 1 | J28: =IF(AND(E28=0,H28=0,I28=0),"일치","차이") -> 차이
A30: 검증 — 미션 파일 「과세+면세」 합계와 대조
A31: 연도 | B31: 구분 | C31: 미션 파일 합계 | D31: 대사내역 집계 | E31: 차이
A32: 2025 | B32: 매입 | C32: 1930985295 | D32: =SUMIFS(대사내역!$K$2:$K$113,대사내역!$A$2:$A$113,A32,대사내역!$C$2:$C$113,B32) -> 1930985295 | E32: =C32-D32 -> 0
A33: 2025 | B33: 매출 | C33: 206782304 | D33: =SUMIFS(대사내역!$K$2:$K$113,대사내역!$A$2:$A$113,A33,대사내역!$C$2:$C$113,B33) -> 206782304 | E33: =C33-D33 -> 0
A34: 2026 | B34: 매입 | C34: 1611376960 | D34: =SUMIFS(대사내역!$K$2:$K$113,대사내역!$A$2:$A$113,A34,대사내역!$C$2:$C$113,B34) -> 1611376960 | E34: =C34-D34 -> 0
A35: 2026 | B35: 매출 | C35: 230531498 | D35: =SUMIFS(대사내역!$K$2:$K$113,대사내역!$A$2:$A$113,A35,대사내역!$C$2:$C$113,B35) -> 230531498 | E35: =C35-D35 -> 0

Sheet 차이·확인사항
A1: 차이 및 확인 필요 사항
A3: No | B3: 분류 | C3: 연월 | D3: 일자 | E3: 구분 | F3: 금액 | G3: 내용 | H3: 조치 제안
A4: 1 | B4: 금액 불일치 | C4: 2026.09 | D4: 09-30 | E4: 매입 | F4: 2160313 | G4: 미션 매입(과세)에 「수입대행 수수료」 2,160,313원이 있으나 태향 원장에 없음 (같은 날 수입원금 19,459,211원은 양쪽 모두 있음) | H4: 태향 원장에 9월 수입대행 수수료 반영 여부 확인
A5: 2 | B5: 금액 불일치 | C5: 2025.12 | D5: 12-10 | E5: 매출 | F5: -202950 | G5: 태향 원장 대변 「25.11월 미션글로벌 부자재 구매비」 -202,950원 — 미션 매출에 대응 전표 없음 | H5: 미션 11월 매출(부자재) 조정 전표 필요 여부 확인
A6: 3 | B6: 원장에만 (순액 0) | C6: 2025.03 | D6: 03-25·26 | E6: 매출·매입 | F6: 850450 | G6: 태향 원장에 「미션(수출운송비)」 대변 850,450 / 차변 850,450 — 미션 장부에는 없음. 서로 상계되어 잔액 영향 없음 | H6: 정정 분개로 보이며 조치 불요, 필요 시 원장에서 삭제
A7: 4 | B7: 계정 오류 | C7: 2025.09 | D7: 09-30 | E7: 매출 | F7: 15010317 | G7: 미션 매출 전표 차변계정이 「미지급금」 — 다른 달은 모두 「외상매출금」 | H7: 외상매출금으로 정정
A8: 5 | B8: 계정 혼용 | C8: 2025.04 | D8: 04-07·30 | E8: 매입 | F8: 4125000 | G8: 물류대행비(기타 수수료 4,125,000) 차변계정이 4월만 「(판)운반비」, 나머지 달은 「상품」 | H8: 계정 통일
A9: 6 | B9: 계정 혼용 | C9: 2025.10 | D9: 10-27 | E9: 매입 | F9: 8254097 | G9: 수입원금 7,173,170 · 수입대행 수수료 1,080,927을 「미착품」으로 처리 — 2025년 다른 달은 「상품」 | H9: 2026년은 수입 건 모두 미착품 → 처리 기준 확인
A10: 7 | B10: 계정 확인 | C10: 2026.03 | D10: 03-31 | E10: 매입 | F10: 454055451 | G10: 월 상품 매입(포멜로 인 시럽 외 373건)을 「미착품」으로 처리 — 다른 달 상품 매입은 「상품」 | H10: 상품으로 정정 또는 미착품 대체 전표 확인
A11: 8 | B11: 계정 확인 | C11: 2026.08 | D11: 08-31 | E11: 매입 | F11: 117283155 | G11: 월 상품 매입(블랙타피오카즉석컵펄 외 282건)을 「미착품」으로 처리 | H11: 위와 동일
A12: 9 | B12: 귀속월 | C12: 2026.01 | D12: 01-31 | E12: 매출 | F12: 14427365 | G12: 적요상 「25.12」 거래(14,103,365 + 324,000)를 양쪽 모두 2026.1월로 처리 — 2025년 매출에서 누락 | H12: 부가세 신고 귀속(2025 2기) 확인
A13: 10 | B13: 귀속월 | C13: 2026.03 | D13: 03-02 | E13: 매출 | F13: 9523137 | G13: 적요상 「2월」 거래를 양쪽 모두 3월 2일로 처리 | H13: 세금계산서 작성일자 확인
A14: 11 | B14: 참고 | C14: 2026.03~06 | E14: 매출 | F14: 57750000 | G14: 우베 파우더 매출 57,750,000(04-14) → 전액 취소(06-29). 원장에는 3/12 「미션글로벌 지급」, 4/16 「(주)미션글로벌」 차변 57,750,000이 2건 있음 (결제내역 시트) | H14: 양쪽 장부는 일치. 지급 2건의 성격(선급·반환 등) 확인
A15: 12 | B15: 참고 | C15: 2025.02 | D15: 02-28 | E15: 매출 | F15: 35266495 | G15: 미션 매출 품명이 「000」 | H15: 품명 보완
A16: 13 | B16: 참고 | C16: 2026.09 | E16: 매입·매출 | G16: 2026년 9월 월말 상품 매출(태향→미션)과 미션 매출 전표가 양쪽 모두 아직 없음 | H16: 9월 마감 후 재대사

Sheet 대사내역
A1: 연도 | B1: 월 | C1: 구분 | D1: 원장 일자 | E1: 원장 적요 (태향 거래처원장) | F1: 원장 금액 | G1: 미션 일자 | H1: 미션 품명 | I1: 유형 | J1: 미션 계정 (차변/대변) | K1: 미션 금액(합계) | L1: 차이 (원장-미션) | M1: 결과 | N1: 비고
A2: 2025 | B2: 1 | C2: 매입 | D2: 01-31 | E2: [RZ] IQF 레몬 슬라이스 500G960 X 2,200 | F2: 2112000 | G2: 01-31 | H2: [RZ] IQF 레몬 슬라이스 500G | I2: 면세 | J2: 상품 / 미지급금 | K2: 2112000 | L2: =N(F2)-N(K2) -> 0 | M2: =IF(F2="","미션에만",IF(K2="","원장에만",IF(L2=0,"일치","금액차이"))) -> 일치
A3: 2025 | B3: 1 | C3: 매입 | D3: 01-31 | E3: [네이쳐티]NEW 바닐라빈파우더 1KG 외 523건 | F3: 184663129 | G3: 01-31 | H3: [네이쳐티]NEW 바닐라빈파우더 1KG 외 523건 | I3: 과세 | J3: 상품 / 미지급금 | K3: 184663129 | L3: =N(F3)-N(K3) -> 0 | M3: =IF(F3="","미션에만",IF(K3="","원장에만",IF(L3=0,"일치","금액차이"))) -> 일치
A4: 2025 | B4: 1 | C4: 매입 | D4: 01-31 | E4: [물류대행비]기타 수수료 1 X 3,750,000 | F4: 4125000 | G4: 01-31 | H4: [물류대행비]기타 수수료 | I4: 과세 | J4: 상품 / 미지급금 | K4: 4125000 | L4: =N(F4)-N(K4) -> 0 | M4: =IF(F4="","미션에만",IF(K4="","원장에만",IF(L4=0,"일치","금액차이"))) -> 일치
A5: 2025 | B5: 2 | C5: 매입 | D5: 02-28 | E5: [네이쳐티/원두]하우스블렌드 1KG 외 272건 | F5: 94994956 | G5: 02-28 | H5: [네이쳐티/원두]하우스블렌드 1KG 외 272건 | I5: 과세 | J5: 상품 / 미지급금 | K5: 94994956 | L5: =N(F5)-N(K5) -> 0 | M5: =IF(F5="","미션에만",IF(K5="","원장에만",IF(L5=0,"일치","금액차이"))) -> 일치
A6: 2025 | B6: 2 | C6: 매입 | D6: 02-28 | E6: [RZ] IQF 레몬 슬라이스 500G960 X 2,090 | F6: 2006400 | G6: 02-28 | H6: [RZ] IQF 레몬 슬라이스 500G | I6: 면세 | J6: 상품 / 미지급금 | K6: 2006400 | L6: =N(F6)-N(K6) -> 0 | M6: =IF(F6="","미션에만",IF(K6="","원장에만",IF(L6=0,"일치","금액차이"))) -> 일치
A7: 2025 | B7: 2 | C7: 매입 | D7: 02-28 | E7: [물류대행비]기타 수수료 1 X 3,750,000 | F7: 4125000 | G7: 02-28 | H7: [물류대행비]기타 수수료 | I7: 과세 | J7: 상품 / 미지급금 | K7: 4125000 | L7: =N(F7)-N(K7) -> 0 | M7: =IF(F7="","미션에만",IF(K7="","원장에만",IF(L7=0,"일치","금액차이"))) -> 일치
A8: 2025 | B8: 3 | C8: 매입 | D8: 03-10 | E8: [물류대행비]기타 수수료 1 X 3,750,000 | F8: 4125000 | G8: 03-10 | H8: [물류대행비]기타 수수료 | I8: 과세 | J8: 상품 / 미지급금 | K8: 4125000 | L8: =N(F8)-N(K8) -> 0 | M8: =IF(F8="","미션에만",IF(K8="","원장에만",IF(L8=0,"일치","금액차이"))) -> 일치
A9: 2025 | B9: 3 | C9: 매입 | D9: 03-10 | E9: [물류대행비]기타 수수료 -1 X 3,750,000 | F9: -4125000 | G9: 03-10 | H9: [물류대행비]기타 수수료 | I9: 과세 | J9: 상품 / 미지급금 | K9: -4125000 | L9: =N(F9)-N(K9) -> 0 | M9: =IF(F9="","미션에만",IF(K9="","원장에만",IF(L9=0,"일치","금액차이"))) -> 일치
A10: 2025 | B10: 3 | C10: 매입 | D10: 03-26 | E10: 미션（수출운송비） | F10: 850450 | L10: =N(F10)-N(K10) -> 850450 | M10: =IF(F10="","미션에만",IF(K10="","원장에만",IF(L10=0,"일치","금액차이"))) -> 원장에만 | N10: 원장에만 있음: 수출운송비 — 03-25 대변과 상계되어 순액 0
A11: 2025 | B11: 3 | C11: 매입 | D11: 03-31 | E11: (D)[RZ] IQF 수박주스 [200G*50BAGS] [200G*50BAGS]1,000 X 760 | F11: 3222400 | G11: 03-31 | H11: (D)[RZ] IQF 수박주스 [200G*50BAGS] [200G*50BAGS] | I11: 면세 | J11: 상품 / 미지급금 | K11: 3222400 | L11: =N(F11)-N(K11) -> 0 | M11: =IF(F11="","미션에만",IF(K11="","원장에만",IF(L11=0,"일치","금액차이"))) -> 일치 | N11: 미션 면세 구간 제목이 「과세」로 표기됨(유형은 면세)
A12: 2025 | B12: 3 | C12: 매입 | D12: 03-31 | E12: [물류대행비]기타 수수료 1 X 3,750,000 | F12: 4125000 | G12: 03-31 | H12: [물류대행비]기타 수수료 | I12: 과세 | J12: 상품 / 미지급금 | K12: 4125000 | L12: =N(F12)-N(K12) -> 0 | M12: =IF(F12="","미션에만",IF(K12="","원장에만",IF(L12=0,"일치","금액차이"))) -> 일치
A13: 2025 | B13: 3 | C13: 매입 | D13: 03-31 | E13: [기타]기타판매(라임에이드 2월 단가 누락건) 외 759건 | F13: 77035897 | G13: 03-31 | H13: [기타]기타판매(라임에이드 2월 단가 누락건) 외 759건 | I13: 과세 | J13: 상품 / 미지급금 | K13: 77035897 | L13: =N(F13)-N(K13) -> 0 | M13: =IF(F13="","미션에만",IF(K13="","원장에만",IF(L13=0,"일치","금액차이"))) -> 일치
A14: 2025 | B14: 4 | C14: 매입 | D14: 04-07 | E14: [물류대행비]기타 수수료 1 X 3,750,000 | F14: 4125000 | G14: 04-07 | H14: [물류대행비]기타 수수료 | I14: 과세 | J14: (판)운반비 / 미지급금 | K14: 4125000 | L14: =N(F14)-N(K14) -> 0 | M14: =IF(F14="","미션에만",IF(K14="","원장에만",IF(L14=0,"일치","금액차이"))) -> 일치 | N14: 물류대행비 계정이 「(판)운반비」 — 다른 달은 「상품」 (계정 혼용)
A15: 2025 | B15: 4 | C15: 매입 | D15: 04-07 | E15: [물류대행비]기타 수수료 -1 X 3,750,000 | F15: -4125000 | G15: 04-07 | H15: [물류대행비]기타 수수료 | I15: 과세 | J15: (판)운반비 / 미지급금 | K15: -4125000 | L15: =N(F15)-N(K15) -> 0 | M15: =IF(F15="","미션에만",IF(K15="","원장에만",IF(L15=0,"일치","금액차이"))) -> 일치 | N15: 물류대행비 계정이 「(판)운반비」 — 다른 달은 「상품」 (계정 혼용)
A16: 2025 | B16: 4 | C16: 매입 | D16: 04-16 | E16: 베트코코 수입대행 USD 3,520 * 1,439.6 | F16: 5067392 | G16: 04-16 | H16: 베트코코 수입대행 USD 3,520 * 1,439.6 | I16: 과세 | J16: 상품 / 미지급금 | K16: 5067392 | L16: =N(F16)-N(K16) -> 0 | M16: =IF(F16="","미션에만",IF(K16="","원장에만",IF(L16=0,"일치","금액차이"))) -> 일치
A17: 2025 | B17: 4 | C17: 매입 | D17: 04-16 | E17: 베트코코 수입대행 (BL:MJSG25030110) | F17: 611190 | G17: 04-16 | H17: 베트코코 수입대행 (BL:MJSG25030110) | I17: 과세 | J17: 상품 / 미지급금 | K17: 611190 | L17: =N(F17)-N(K17) -> 0 | M17: =IF(F17="","미션에만",IF(K17="","원장에만",IF(L17=0,"일치","금액차이"))) -> 일치
A18: 2025 | B18: 4 | C18: 매입 | D18: 04-30 | E18: [물류대행비]기타 수수료 1 X 3,750,000 | F18: 4125000 | G18: 04-30 | H18: [물류대행비]기타 수수료 | I18: 과세 | J18: (판)운반비 / 미지급금 | K18: 4125000 | L18: =N(F18)-N(K18) -> 0 | M18: =IF(F18="","미션에만",IF(K18="","원장에만",IF(L18=0,"일치","금액차이"))) -> 일치 | N18: 물류대행비 계정이 「(판)운반비」 — 다른 달은 「상품」 (계정 혼용)
A19: 2025 | B19: 4 | C19: 매입 | D19: 04-30 | E19: [GE]화이트펄(곤약) 1KG 외 321건 | F19: 178105869 | G19: 04-30 | H19: [GE]화이트펄(곤약) 1KG 외 321건 | I19: 과세 | J19: 상품 / 미지급금 | K19: 178105869 | L19: =N(F19)-N(K19) -> 0 | M19: =IF(F19="","미션에만",IF(K19="","원장에만",IF(L19=0,"일치","금액차이"))) -> 일치
A20: 2025 | B20: 4 | C20: 매입 | D20: 04-30 | E20: [RZ] IQF 레몬 슬라이스 500G960 X 2,090 | F20: 3184400 | G20: 04-30 | H20: [RZ] IQF 레몬 슬라이스 500G | I20: 면세 | J20: 상품 / 미지급금 | K20: 3184400 | L20: =N(F20)-N(K20) -> 0 | M20: =IF(F20="","미션에만",IF(K20="","원장에만",IF(L20=0,"일치","금액차이"))) -> 일치
A21: 2025 | B21: 5 | C21: 매입 | D21: 05-31 | E21: 기타 수수료 1 X 3,750,000 | F21: 4125000 | G21: 05-31 | H21: 기타 수수료 | I21: 과세 | J21: 상품 / 미지급금 | K21: 4125000 | L21: =N(F21)-N(K21) -> 0 | M21: =IF(F21="","미션에만",IF(K21="","원장에만",IF(L21=0,"일치","금액차이"))) -> 일치
A22: 2025 | B22: 5 | C22: 매입 | D22: 05-31 | E22: [GEV]화이트펄(곤약) 1KG 외 390건 | F22: 177074496 | G22: 05-31 | H22: [GEV]화이트펄(곤약) 1KG 외 390건 | I22: 과세 | J22: 상품 / 미지급금 | K22: 177074496 | L22: =N(F22)-N(K22) -> 0 | M22: =IF(F22="","미션에만",IF(K22="","원장에만",IF(L22=0,"일치","금액차이"))) -> 일치
A23: 2025 | B23: 5 | C23: 매입 | D23: 05-31 | E23: (D)[RZ] IQF 수박주스 [200G*50BAGS] [200G*50BAGS]800 X 760 | F23: 1649200 | G23: 05-31 | H23: (D)[RZ] IQF 수박주스 [200G*50BAGS] [200G*50BAGS] | I23: 면세 | J23: 상품 / 미지급금 | K23: 1649200 | L23: =N(F23)-N(K23) -> 0 | M23: =IF(F23="","미션에만",IF(K23="","원장에만",IF(L23=0,"일치","금액차이"))) -> 일치
A24: 2025 | B24: 6 | C24: 매입 | D24: 06-04 | E24: 수입대행 수수료 1 X 1,697,028 | F24: 1866731 | G24: 06-04 | H24: 수입대행 수수료 | I24: 과세 | J24: 상품 / 미지급금 | K24: 1866731 | L24: =N(F24)-N(K24) -> 0 | M24: =IF(F24="","미션에만",IF(K24="","원장에만",IF(L24=0,"일치","금액차이"))) -> 일치
A25: 2025 | B25: 6 | C25: 매입 | D25: 06-04 | E25: 수입원금 1 X 13,690,277 | F25: 15059305 | G25: 06-04 | H25: 수입원금 | I25: 과세 | J25: 상품 / 미지급금 | K25: 15059305 | L25: =N(F25)-N(K25) -> 0 | M25: =IF(F25="","미션에만",IF(K25="","원장에만",IF(L25=0,"일치","금액차이"))) -> 일치
A26: 2025 | B26: 6 | C26: 매입 | D26: 06-04 | E26: 수입원금 -1 X 13,690,277 | F26: -15059305 | G26: 06-04 | H26: 수입원금 | I26: 과세 | J26: 상품 / 미지급금 | K26: -15059305 | L26: =N(F26)-N(K26) -> 0 | M26: =IF(F26="","미션에만",IF(K26="","원장에만",IF(L26=0,"일치","금액차이"))) -> 일치
A27: 2025 | B27: 6 | C27: 매입 | D27: 06-04 | E27: 수입대행 그레잇이스턴 베트남 2-2번 $9,641.04*1420 | F27: 13690277 | G27: 06-04 | H27: 수입대행 그레잇이스턴 베트남 2-2번 $9,641.04*1420 | I27: 면세 | J27: 상품 / 미지급금 | K27: 13690277 | L27: =N(F27)-N(K27) -> 0 | M27: =IF(F27="","미션에만",IF(K27="","원장에만",IF(L27=0,"일치","금액차이"))) -> 일치
A28: 2025 | B28: 6 | C28: 매입 | D28: 06-30 | E28: (D)[RZ] IQF 수박주스 [200G*50BAGS] [200G*50BAGS]1,600 X 760 | F28: 3647730 | G28: 06-30 | H28: (D)[RZ] IQF 수박주스 [200G*50BAGS] [200G*50BAGS] | I28: 면세 | J28: 상품 / 미지급금 | K28: 3647730 | L28: =N(F28)-N(K28) -> 0 | M28: =IF(F28="","미션에만",IF(K28="","원장에만",IF(L28=0,"일치","금액차이"))) -> 일치
A29: 2025 | B29: 6 | C29: 매입 | D29: 06-30 | E29: 기타 수수료 1 X 3,750,000 | F29: 4125000 | G29: 06-30 | H29: 기타 수수료 | I29: 과세 | J29: 상품 / 미지급금 | K29: 4125000 | L29: =N(F29)-N(K29) -> 0 | M29: =IF(F29="","미션에만",IF(K29="","원장에만",IF(L29=0,"일치","금액차이"))) -> 일치
A30: 2025 | B30: 6 | C30: 매입 | D30: 06-30 | E30: [SN]브라운 슈가 베이스 2.5KG 외 407건 | F30: 170193463 | G30: 06-30 | H30: [SN]브라운 슈가 베이스 2.5KG 외 407건 | I30: 과세 | J30: 상품 / 미지급금 | K30: 170193463 | L30: =N(F30)-N(K30) -> 0 | M30: =IF(F30="","미션에만",IF(K30="","원장에만",IF(L30=0,"일치","금액차이"))) -> 일치
... A46: 2025 | B46: 10 | C46: 매입 | D46: 10-27 | E46: 그레잇이스턴 베트남 스카이 수수료1 X 273,611.58 | F46: 504625 | G46: 10-27 | H46: 그레잇이스턴 베트남 스카이 수수료 | I46: 면세 | J46: 상품 / 미지급금 | K46: 504625 | L46: =N(F46)-N(K46) -> 0 | M46: =IF(F46="","미션에만",IF(K46="","원장에만",IF(L46=0,"일치","금액차이"))) -> 일치
A47: 2025 | B47: 10 | C47: 매입 | D47: 10-27 | E47: 수입대행 수수료 1 X 982,661 | F47: 1080927 | G47: 10-27 | H47: 수입대행 수수료 | I47: 과세 | J47: 미착품 / 미지급금 | K47: 1080927 | L47: =N(F47)-N(K47) -> 0 | M47: =IF(F47="","미션에만",IF(K47="","원장에만",IF(L47=0,"일치","금액차이"))) -> 일치 | N47: 수입대행 수수료 계정이 「미착품」 — 2025년 다른 수수료는 「상품」
A48: 2025 | B48: 10 | C48: 매입 | D48: 10-27 | E48: 수입원금1 X 7,173,170 | F48: 7173170 | G48: 10-27 | H48: 수입원금 | I48: 면세 | J48: 미착품 / 미지급금 | K48: 7173170 | L48: =N(F48)-N(K48) -> 0 | M48: =IF(F48="","미션에만",IF(K48="","원장에만",IF(L48=0,"일치","금액차이"))) -> 일치 | N48: 수입원금 계정이 「미착품」 — 2025년 다른 수입원금은 「상품」
A49: 2025 | B49: 10 | C49: 매입 | D49: 10-31 | E49: [네이쳐티]NEW 로얄밀크티파우더 1KG 외 338건 | F49: 195941305 | G49: 10-31 | H49: [네이쳐티]NEW 로얄밀크티파우더 1KG 외 338건 | I49: 과세 | J49: 상품 / 미지급금 | K49: 195941305 | L49: =N(F49)-N(K49) -> 0 | M49: =IF(F49="","미션에만",IF(K49="","원장에만",IF(L49=0,"일치","금액차이"))) -> 일치
A50: 2025 | B50: 10 | C50: 매입 | D50: 10-31 | E50: 기타 수수료 1 X 3,750,000 | F50: 4125000 | G50: 10-31 | H50: 기타 수수료 | I50: 과세 | J50: 상품 / 미지급금 | K50: 4125000 | L50: =N(F50)-N(K50) -> 0 | M50: =IF(F50="","미션에만",IF(K50="","원장에만",IF(L50=0,"일치","금액차이"))) -> 일치
A51: 2025 | B51: 10 | C51: 매입 | D51: 10-31 | E51: [RZ] IQF 레몬 슬라이스 500G480 X 2,090 | F51: 1915200 | G51: 10-31 | H51: [RZ] IQF 레몬 슬라이스 500G | I51: 면세 | J51: 상품 / 미지급금 | K51: 1915200 | L51: =N(F51)-N(K51) -> 0 | M51: =IF(F51="","미션에만",IF(K51="","원장에만",IF(L51=0,"일치","금액차이"))) -> 일치
A52: 2025 | B52: 11 | C52: 매입 | D52: 11-07 | E52: 기타 수수료 1 X 3,750,000 | F52: 4125000 | G52: 11-07 | H52: 기타 수수료 | I52: 과세 | J52: 상품 / 미지급금 | K52: 4125000 | L52: =N(F52)-N(K52) -> 0 | M52: =IF(F52="","미션에만",IF(K52="","원장에만",IF(L52=0,"일치","금액차이"))) -> 일치
A53: 2025 | B53: 11 | C53: 매입 | D53: 11-30 | E53: [네이쳐티]NEW 초코파우더 800G 외 305건 | F53: 135509733 | G53: 11-30 | H53: [네이쳐티]NEW 초코파우더 800G 외 305건 | I53: 과세 | J53: 상품 / 미지급금 | K53: 135509733 | L53: =N(F53)-N(K53) -> 0 | M53: =IF(F53="","미션에만",IF(K53="","원장에만",IF(L53=0,"일치","금액차이"))) -> 일치
A54: 2025 | B54: 11 | C54: 매입 | D54: 11-30 | E54: [RZ] IQF 레몬 슬라이스 500G400 X 2,090 | F54: 1531970 | G54: 11-30 | H54: [RZ] IQF 레몬 슬라이스 500G | I54: 면세 | J54: 상품 / 미지급금 | K54: 1531970 | L54: =N(F54)-N(K54) -> 0 | M54: =IF(F54="","미션에만",IF(K54="","원장에만",IF(L54=0,"일치","금액차이"))) -> 일치
A55: 2025 | B55: 12 | C55: 매입 | D55: 12-03 | E55: 차량 매매 80나 3652 | F55: 13000000 | G55: 12-03 | H55: 차량 매매 80나 3652 (중고트럭매매) | I55: 과세 | J55: 차량운반구 / 미지급금 | K55: 13000000 | L55: =N(F55)-N(K55) -> 0 | M55: =IF(F55="","미션에만",IF(K55="","원장에만",IF(L55=0,"일치","금액차이"))) -> 일치
...

Sheet 결제내역(참고)
A1: 연도 | B1: 월 | C1: 일자 | D1: 적요 | E1: 차변 | F1: 대변
A2: 2025 | B2: 1 | C2: 01-20 | D2: （주）미션글로벌 | F2: 40000000
A3: 2025 | B3: 2 | C3: 02-05 | D3: （주）미션글로벌 | F3: 50000000
A4: 2025 | B4: 3 | C4: 03-04 | D4: （주）미션글로벌 | F4: 50000000
A5: 2025 | B5: 3 | C5: 03-24 | D5: （주）미션글로벌 | F5: 40000000
A6: 2025 | B6: 4 | C6: 04-03 | D6: （주）미션글로벌 | F6: 58545996
A7: 2025 | B7: 4 | C7: 04-25 | D7: （주）미션글로벌 | F7: 50000000
A8: 2025 | B8: 4 | C8: 04-30 | D8: （주）미션글로벌 | F8: 50000000
A9: 2025 | B9: 5 | C9: 05-30 | D9: （주）미션글로벌 | F9: 100000000
A10: 2025 | B10: 6 | C10: 06-05 | D10: （주）미션글로벌 | F10: 22454593
A11: 2025 | B11: 6 | C11: 06-05 | D11: （주）미션글로벌 | F11: 16926035
A12: 2025 | B12: 7 | C12: 07-03 | D12: （주）미션글로벌 | F12: 120000000
A13: 2025 | B13: 7 | C13: 07-21 | D13: （주）미션글로벌 | F13: 30000000
... A34: 2026 | B34: 3 | C34: 03-06 | D34: （주）미션글로벌_2월 | F34: 30000000
A35: 2026 | B35: 3 | C35: 03-12 | D35: 미션글로벌 지급 | E35: 57750000
A36: 2026 | B36: 4 | C36: 04-03 | D36: （주）미션글로벌_2월 | F36: 59092675
A37: 2026 | B37: 4 | C37: 04-16 | D37: （주）미션글로벌 | E37: 57750000
A38: 2026 | B38: 4 | C38: 04-30 | D38: （주）미션글로벌_4월 | F38: 100000000
A39: 2026 | B39: 5 | C39: 05-22 | D39: （주）미션글로벌_3월 | F39: 100000000
A40: 2026 | B40: 5 | C40: 05-26 | D40: （주）미션글로벌_3월 | F40: 37904324
A41: 2026 | B41: 5 | C41: 05-27 | D41: （주）미션글로벌_4월 | F41: 100000000
A42: 2026 | B42: 6 | C42: 06-05 | D42: （주）미션글로벌_4월 | F42: 63385911
A43: 2026 | B43: 6 | C43: 06-19 | D43: (주)미션글로벌 3월 | F43: 50000000
A44: 2026 | B44: 6 | C44: 06-25 | D44: （주）미션글로벌 5월 | F44: 50000000
A45: 2026 | B45: 6 | C45: 06-26 | D45: （주）미션글로벌 5월 | F45: 30000000
A46: 2026 | B46: 7 | C46: 07-10 | D46: （주）미션글로벌_6월 | F46: 40000000
A47: 2026 | B47: 7 | C47: 07-15 | D47: （주）미션글로벌_6월 | F47: 40000000
A48: 2026 | B48: 7 | C48: 07-20 | D48: （주）미션글로벌_6월 | F48: 40000000
A49: 2026 | B49: 7 | C49: 07-22 | D49: （주）미션글로벌_6월 | F49: 40000000
... A59: 2026 | B59: 10 | C59: 10-01 | D59: （주）미션글로벌_26.08월 | F59: 35531255
D60: 합계 | E60: =SUM(E2:E59) -> 115500000 | F60: =SUM(F2:F59) -> 2875123447
